Workbook
Name finishdate: Sheet1!$G$2
Name Startdate: Sheet1!$F$2

Sheet Sheet1
C1: Task | D1: No of Men | E1: No Of Days | F1: Start Date | G1: Finish date
C2: Dates | F2: 46266 | G2: 46346
C3: Cable delivery 1 | E3: 1 | F3: 46296 | G3: =WORKDAY(F3,E3-1,0) -> 46296
C4: Cable delivery 2 | E4: 1 | F4: 46297 | G4: =WORKDAY(F4,E4-1,0) -> 46297
C5: Cable delivery 3 | E5: 1 | F5: 46310 | G5: =WORKDAY(F5,E5-1,0) -> 46310
C6: Cable delivery 4 | E6: 1 | F6: 46311 | G6: =WORKDAY(F6,E6-1,0) -> 46311
C8: Initial Works | E8: 28 | F8: 46296 | G8: =WORKDAY(F8,E8-1,0) -> 46335
C9: Manufacturing & installation of containment | D9: 6 | E9: 23 | F9: =Startdate -> 46266 | G9: =WORKDAY(F9,E9-1,0) -> 46296
C10: Moving of Existing whips | D10: 8 | E10: 20 | F10: =Startdate -> 46266 | G10: =WORKDAY(F10,E10-1,0) -> 46293
C11: Delivery 1 Reciving of Whip cables transporting to Electrical rooms | D11: 4 | E11: 1 | F11: =F3 -> 46296 | G11: 46311
C12: Delivery 2 Reciving of Whip cables transporting to Electrical rooms | E12: 1 | F12: =F11 -> 46296 | G12: 46311
C13: Delivery 3 Reciving of Whip cables transporting to Electrical rooms | E13: 1 | F13: =F11 -> 46296 | G13: 46311
C14: Delivery 4 Reciving of Whip cables transporting to Electrical rooms | E14: 1 | F14: =F11 -> 46296 | G14: 46311
C16: Delivery 1 Temp. Labeling of Whip cables | E16: 5 | F16: =F11 -> 46296 | G16: =WORKDAY(F16,E16-1,0) -> 46302
C17: Delivery 2 Temp. Labeling of Whip cables | E17: 5 | F17: =F11 -> 46296 | G17: =WORKDAY(F17,E17-1,0) -> 46302
C18: Delivery 3 Temp. Labeling of Whip cables | E18: 5 | F18: =F11 -> 46296 | G18: =WORKDAY(F18,E18-1,0) -> 46302
C19: Delivery 4 Temp. Labeling of Whip cables | E19: 5 | F19: =F11 -> 46296 | G19: =WORKDAY(F19,E19-1,0) -> 46302
C21: Phases
C22: Phase 1 | D22: 24 | F22: =F57 -> 46296 | G22: =G84 -> 46309
C23: Phase 2 | D23: 24 | F23: =F93 -> 46310 | G23: =G120 -> 46323
C24: Phase 3 | D24: 24 | F24: =F129 -> 46324 | G24: =G156 -> 46337
C25: Phase 4 | D25: 12 | F25: =F165 -> 46338 | G25: =G183 -> 46346
C27: DH 1-1
A28: =+_xlfn.CONCAT("DH ",#REF!," - Panel ",#REF!) -> #REF! | B28: =+_xlfn.CONCAT("DH ",#REF!," - Panel ",#REF!) -> #REF! | C28: DH 1_1 - Panel 7 | E28: =G28-F28 -> 11 | F28: =F3 -> 46296 | G28: =G57 -> 46307 | J28: 46297
A29: =+_xlfn.CONCAT("DH ",#REF!," - Panel ",#REF!) -> #REF! | B29: =+_xlfn.CONCAT("DH ",#REF!," - Panel ",#REF!) -> #REF! | C29: DH 1_1 - Panel 9 | E29: =G29-F29 -> 13 | F29: =F28 -> 46296 | G29: =G66 -> 46309 | J29: 46297
A30: =+_xlfn.CONCAT("DH ",#REF!," - Panel ",#REF!) -> #REF! | B30: =+_xlfn.CONCAT("DH ",#REF!," - Panel ",#REF!) -> #REF! | C30: DH 1_1 - Panel 15 | E30: =G30-F30 -> 11 | F30: =F28 -> 46296 | G30: =G75 -> 46307 | J30: 46310
A31: =+_xlfn.CONCAT("DH ",#REF!," - Panel ",#REF!) -> #REF! | B31: =+_xlfn.CONCAT("DH ",#REF!," - Panel ",#REF!) -> #REF! | C31: DH 1_1 - Panel 17 | E31: =G31-F31 -> 13 | F31: =F28 -> 46296 | G31: =G84 -> 46309 | J31: 46310
A32: =+_xlfn.CONCAT("DH ",#REF!," - Panel ",#REF!) -> #REF! | B32: =+_xlfn.CONCAT("DH ",#REF!," - Panel ",#REF!) -> #REF! | C32: DH 1_1 - Panel 19 | E32: =G32-F32 -> 8 | F32: =G31+1 -> 46310 | G32: =G93 -> 46318 | J32: 46324
A33: =+_xlfn.CONCAT("DH ",#REF!," - Panel ",#REF!) -> #REF! | B33: =+_xlfn.CONCAT("DH ",#REF!," - Panel ",#REF!) -> #REF! | C33: DH 1_1 - Panel 21 | E33: =G33-F33 -> 13 | F33: =F32 -> 46310 | G33: =G102 -> 46323 | J33: 46324
A34: =+_xlfn.CONCAT("DH ",#REF!," - Panel ",#REF!) -> #REF! | B34: =+_xlfn.CONCAT("DH ",#REF!," - Panel ",#REF!) -> #REF! | C34: DH 1_1 - Panel 23 | E34: =G34-F34 -> 8 | F34: =F32 -> 46310 | G34: =G111 -> 46318 | J34: 46338
A35: =+_xlfn.CONCAT("DH ",#REF!," - Panel ",#REF!) -> #REF! | B35: =+_xlfn.CONCAT("DH ",#REF!," - Panel ",#REF!) -> #REF! | C35: DH 1_1 - Panel 25 | E35: =G35-F35 -> 13 | F35: =F32 -> 46310 | G35: =G120 -> 46323 | J35: 46338
A36: =+_xlfn.CONCAT("DH ",#REF!," - Panel ",#REF!) -> #REF! | B36: =+_xlfn.CONCAT("DH ",#REF!," - Panel ",#REF!) -> #REF! | C36: DH 1_1 - Panel 27 | E36: =G36-F36 -> 8 | F36: =G35+1 -> 46324 | G36: =G129 -> 46332 | J36: 46352
A37: =+_xlfn.CONCAT("DH ",#REF!," - Panel ",#REF!) -> #REF! | B37: =+_xlfn.CONCAT("DH ",#REF!," - Panel ",#REF!) -> #REF! | C37: DH 1_1 - Panel 31 | E37: =G37-F37 -> 13 | F37: =F36 -> 46324 | G37: =G138 -> 46337 | J37: 46352
A38: =+_xlfn.CONCAT("DH ",#REF!," - Panel ",#REF!) -> #REF! | B38: =+_xlfn.CONCAT("DH ",#REF!," - Panel ",#REF!) -> #REF! | C38: DH 1_1 - Panel 33 | E38: =G38-F38 -> 8 | F38: =F36 -> 46324 | G38: =G147 -> 46332 | J38: 46366
A39: =+_xlfn.CONCAT("DH ",#REF!," - Panel ",#REF!) -> #REF! | B39: =+_xlfn.CONCAT("DH ",#REF!," - Panel ",#REF!) -> #REF! | C39: DH 1_1 - Panel 39 | E39: =G39-F39 -> 13 | F39: =F36 -> 46324 | G39: =G156 -> 46337 | J39: 46366
A40: =+_xlfn.CONCAT("DH ",#REF!," - Panel ",#REF!) -> #REF! | B40: =+_xlfn.CONCAT("DH ",#REF!," - Panel ",#REF!) -> #REF! | C40: DH 1_1 - Panel 41 | E40: =G40-F40 -> 8 | F40: =G39+1 -> 46338 | G40: =G165 -> 46346 | J40: 46380
A41: =+_xlfn.CONCAT("DH ",#REF!," - Panel ",#REF!) -> #REF! | B41: =+_xlfn.CONCAT("DH ",#REF!," - Panel ",#REF!) -> #REF! | C41: DH 1_1 - Panel 45 | E41: =G41-F41 -> 13 | F41: =F40 -> 46338 | G41: =G174 -> 46351 | J41: 46391
A42: =+_xlfn.CONCAT("DH ",#REF!," - Panel ",#REF!) -> #REF! | B42: =+_xlfn.CONCAT("DH ",#REF!," - Panel ",#REF!) -> #REF! | C42: DH 1_1 - Panel 47 | E42: =G42-F42 -> 8 | F42: =F40 -> 46338 | G42: =G183 -> 46346 | J42: 46391
C43: DH 2-2
A44: =+_xlfn.CONCAT("DH ",#REF!," - Panel ",#REF!) -> #REF! | B44: =+_xlfn.CONCAT("DH ",#REF!," - Panel ",#REF!) -> #REF! | C44: DH 2_2 - Panel 9 | E44: =G44-F44 -> 11 | F44: =F28 -> 46296 | G44: =G28 -> 46307 | J44: =J28 -> 46297
...

Sheet Manloader
A1: Date | B1: No Of Men Required | C1: Acctual No Of Men | D1: Offset | E1: Working Week
A2: =Startdate -> 46266 | B2: =SUMIFS(Sheet1!$D:$D,Sheet1!$F:$F,"<="&A2,Sheet1!$G:$G,">="&A2) -> 14 | D2: =B2-C2 -> 14 | E2: WW36
A3: =WORKDAY(A2,1,0) -> 46267 | B3: =SUMIFS(Sheet1!$D:$D,Sheet1!$F:$F,"<="&A3,Sheet1!$G:$G,">="&A3) -> 14 | D3: =B3-C3 -> 14
A4: =WORKDAY(A3,1,0) -> 46268 | B4: =SUMIFS(Sheet1!$D:$D,Sheet1!$F:$F,"<="&A4,Sheet1!$G:$G,">="&A4) -> 14 | D4: =B4-C4 -> 14
A5: =WORKDAY(A4,1,0) -> 46269 | B5: =SUMIFS(Sheet1!$D:$D,Sheet1!$F:$F,"<="&A5,Sheet1!$G:$G,">="&A5) -> 14 | D5: =B5-C5 -> 14
A6: =WORKDAY(A5,1,0) -> 46272 | B6: =SUMIFS(Sheet1!$D:$D,Sheet1!$F:$F,"<="&A6,Sheet1!$G:$G,">="&A6) -> 14 | D6: =B6-C6 -> 14 | E6: WW37
A7: =WORKDAY(A6,1,0) -> 46273 | B7: =SUMIFS(Sheet1!$D:$D,Sheet1!$F:$F,"<="&A7,Sheet1!$G:$G,">="&A7) -> 14 | D7: =B7-C7 -> 14
A8: =WORKDAY(A7,1,0) -> 46274 | B8: =SUMIFS(Sheet1!$D:$D,Sheet1!$F:$F,"<="&A8,Sheet1!$G:$G,">="&A8) -> 14 | D8: =B8-C8 -> 14
A9: =WORKDAY(A8,1,0) -> 46275 | B9: =SUMIFS(Sheet1!$D:$D,Sheet1!$F:$F,"<="&A9,Sheet1!$G:$G,">="&A9) -> 14 | D9: =B9-C9 -> 14 | P9: 354
A10: =WORKDAY(A9,1,0) -> 46276 | B10: =SUMIFS(Sheet1!$D:$D,Sheet1!$F:$F,"<="&A10,Sheet1!$G:$G,">="&A10) -> 14 | D10: =B10-C10 -> 14 | E10: WW38 | P10: 8
A11: =WORKDAY(A10,1,0) -> 46279 | B11: =SUMIFS(Sheet1!$D:$D,Sheet1!$F:$F,"<="&A11,Sheet1!$G:$G,">="&A11) -> 14 | D11: =B11-C11 -> 14 | P11: =P9*P10 -> 2832
A12: =WORKDAY(A11,1,0) -> 46280 | B12: =SUMIFS(Sheet1!$D:$D,Sheet1!$F:$F,"<="&A12,Sheet1!$G:$G,">="&A12) -> 14 | D12: =B12-C12 -> 14
A13: =WORKDAY(A12,1,0) -> 46281 | B13: =SUMIFS(Sheet1!$D:$D,Sheet1!$F:$F,"<="&A13,Sheet1!$G:$G,">="&A13) -> 14 | D13: =B13-C13 -> 14
A14: =WORKDAY(A13,1,0) -> 46282 | B14: =SUMIFS(Sheet1!$D:$D,Sheet1!$F:$F,"<="&A14,Sheet1!$G:$G,">="&A14) -> 14 | D14: =B14-C14 -> 14 | E14: WW39
A15: =WORKDAY(A14,1,0) -> 46283 | B15: =SUMIFS(Sheet1!$D:$D,Sheet1!$F:$F,"<="&A15,Sheet1!$G:$G,">="&A15) -> 14 | D15: =B15-C15 -> 14
A16: =WORKDAY(A15,1,0) -> 46286 | B16: =SUMIFS(Sheet1!$D:$D,Sheet1!$F:$F,"<="&A16,Sheet1!$G:$G,">="&A16) -> 14 | D16: =B16-C16 -> 14
A17: =WORKDAY(A16,1,0) -> 46287 | B17: =SUMIFS(Sheet1!$D:$D,Sheet1!$F:$F,"<="&A17,Sheet1!$G:$G,">="&A17) -> 14 | D17: =B17-C17 -> 14
A18: =WORKDAY(A17,1,0) -> 46288 | B18: =SUMIFS(Sheet1!$D:$D,Sheet1!$F:$F,"<="&A18,Sheet1!$G:$G,">="&A18) -> 14 | D18: =B18-C18 -> 14 | E18: WW40
A19: =WORKDAY(A18,1,0) -> 46289 | B19: =SUMIFS(Sheet1!$D:$D,Sheet1!$F:$F,"<="&A19,Sheet1!$G:$G,">="&A19) -> 14 | D19: =B19-C19 -> 14
A20: =WORKDAY(A19,1,0) -> 46290 | B20: =SUMIFS(Sheet1!$D:$D,Sheet1!$F:$F,"<="&A20,Sheet1!$G:$G,">="&A20) -> 14 | D20: =B20-C20 -> 14
A21: =WORKDAY(A20,1,0) -> 46293 | B21: =SUMIFS(Sheet1!$D:$D,Sheet1!$F:$F,"<="&A21,Sheet1!$G:$G,">="&A21) -> 14 | D21: =B21-C21 -> 14
A22: =WORKDAY(A21,1,0) -> 46294 | B22: =SUMIFS(Sheet1!$D:$D,Sheet1!$F:$F,"<="&A22,Sheet1!$G:$G,">="&A22) -> 6 | D22: =B22-C22 -> 6 | E22: WW41
A23: =WORKDAY(A22,1,0) -> 46295 | B23: =SUMIFS(Sheet1!$D:$D,Sheet1!$F:$F,"<="&A23,Sheet1!$G:$G,">="&A23) -> 6 | D23: =B23-C23 -> 6
A24: =WORKDAY(A23,1,0) -> 46296 | B24: =SUMIFS(Sheet1!$D:$D,Sheet1!$F:$F,"<="&A24,Sheet1!$G:$G,">="&A24) -> 34 | D24: =B24-C24 -> 34
A25: =WORKDAY(A24,1,0) -> 46297 | B25: =SUMIFS(Sheet1!$D:$D,Sheet1!$F:$F,"<="&A25,Sheet1!$G:$G,">="&A25) -> 28 | D25: =B25-C25 -> 28
A26: =WORKDAY(A25,1,0) -> 46300 | B26: =SUMIFS(Sheet1!$D:$D,Sheet1!$F:$F,"<="&A26,Sheet1!$G:$G,">="&A26) -> 28 | D26: =B26-C26 -> 28 | E26: WW42
A27: =WORKDAY(A26,1,0) -> 46301 | B27: =SUMIFS(Sheet1!$D:$D,Sheet1!$F:$F,"<="&A27,Sheet1!$G:$G,">="&A27) -> 28 | D27: =B27-C27 -> 28
A28: =WORKDAY(A27,1,0) -> 46302 | B28: =SUMIFS(Sheet1!$D:$D,Sheet1!$F:$F,"<="&A28,Sheet1!$G:$G,">="&A28) -> 28 | D28: =B28-C28 -> 28
A29: =WORKDAY(A28,1,0) -> 46303 | B29: =SUMIFS(Sheet1!$D:$D,Sheet1!$F:$F,"<="&A29,Sheet1!$G:$G,">="&A29) -> 28 | D29: =B29-C29 -> 28
A30: =WORKDAY(A29,1,0) -> 46304 | B30: =SUMIFS(Sheet1!$D:$D,Sheet1!$F:$F,"<="&A30,Sheet1!$G:$G,">="&A30) -> 28 | D30: =B30-C30 -> 28 | E30: WW43
A31: =WORKDAY(A30,1,0) -> 46307 | B31: =SUMIFS(Sheet1!$D:$D,Sheet1!$F:$F,"<="&A31,Sheet1!$G:$G,">="&A31) -> 28 | D31: =B31-C31 -> 28
A32: =WORKDAY(A31,1,0) -> 46308 | B32: =SUMIFS(Sheet1!$D:$D,Sheet1!$F:$F,"<="&A32,Sheet1!$G:$G,">="&A32) -> 28 | D32: =B32-C32 -> 28
A33: =WORKDAY(A32,1,0) -> 46309 | B33: =SUMIFS(Sheet1!$D:$D,Sheet1!$F:$F,"<="&A33,Sheet1!$G:$G,">="&A33) -> 28 | D33: =B33-C33 -> 28
A34: =WORKDAY(A33,1,0) -> 46310 | B34: =SUMIFS(Sheet1!$D:$D,Sheet1!$F:$F,"<="&A34,Sheet1!$G:$G,">="&A34) -> 28 | D34: =B34-C34 -> 28 | E34: WW44
A35: =WORKDAY(A34,1,0) -> 46311 | B35: =SUMIFS(Sheet1!$D:$D,Sheet1!$F:$F,"<="&A35,Sheet1!$G:$G,">="&A35) -> 28 | D35: =B35-C35 -> 28
A36: =WORKDAY(A35,1,0) -> 46314 | B36: =SUMIFS(Sheet1!$D:$D,Sheet1!$F:$F,"<="&A36,Sheet1!$G:$G,">="&A36) -> 24 | D36: =B36-C36 -> 24
A37: =WORKDAY(A36,1,0) -> 46315 | B37: =SUMIFS(Sheet1!$D:$D,Sheet1!$F:$F,"<="&A37,Sheet1!$G:$G,">="&A37) -> 24 | D37: =B37-C37 -> 24
A38: =WORKDAY(A37,1,0) -> 46316 | B38: =SUMIFS(Sheet1!$D:$D,Sheet1!$F:$F,"<="&A38,Sheet1!$G:$G,">="&A38) -> 24 | D38: =B38-C38 -> 24 | E38: WW45
A39: =WORKDAY(A38,1,0) -> 46317 | B39: =SUMIFS(Sheet1!$D:$D,Sheet1!$F:$F,"<="&A39,Sheet1!$G:$G,">="&A39) -> 24 | D39: =B39-C39 -> 24
A40: =WORKDAY(A39,1,0) -> 46318 | B40: =SUMIFS(Sheet1!$D:$D,Sheet1!$F:$F,"<="&A40,Sheet1!$G:$G,">="&A40) -> 24 | D40: =B40-C40 -> 24
...
